<?xml version="1.0" encoding="utf-8"?>
<!-- This URDF was automatically created by SolidWorks to URDF Exporter! Originally created by Stephen Brawner (brawner@gmail.com) 
     Commit Version: 1.6.0-4-g7f85cfe  Build Version: 1.6.7995.38578
     For more information, please see http://wiki.ros.org/sw_urdf_exporter -->
<robot
  name="acromonk">
  <joint name="base_weld" type="fixed">
      <origin
      xyz="0 0 0"
      rpy="0 0 0" /> 
      <parent link="world"/>
      <child link="Base"/>
  </joint>    
  <link
    name="Base">
    <inertial>
      <origin
        xyz="0.0536 0.69428 -0.16917"
        rpy="0 0 0" />
      <mass
        value="5.9209" />
      <inertia
        ixx="0.86611"
        ixy="3.0201E-12"
        ixz="-8.3865E-08"
        iyy="0.13388"
        iyz="2.0135E-12"
        izz="0.76254" />
    </inertial>
    <visual>
      <origin
        xyz="0 0 0"
        rpy="0 0 0" />
      <geometry>
        <mesh
          filename="meshes/Base.obj" />
      </geometry>
      <material
        name="">
        <color
          rgba="0.79216 0.81961 0.93333 1" />
      </material>
    </visual>
  </link>
  <link
    name="stick_2">
    <inertial>
      <origin
        xyz="0.0536 0 0"
        rpy="0 0 0" />
      <mass
        value="0.062168" />
      <inertia
        ixx="4.4463E-06"
        ixy="-1.0251E-21"
        ixz="1.5345E-20"
        iyy="0.00084889"
        iyz="-2.4293E-22"
        izz="0.00084889" />
    </inertial>
    <visual>
      <origin
        xyz="0 0 0"
        rpy="0 0 0" />
      <geometry>
        <mesh
          filename="meshes/stick_2.obj" />
      </geometry>
      <material
        name="">
        <color
          rgba="1 1 1 1" />
      </material>
    </visual>
  </link>
  <joint
    name="stick_2"
    type="fixed">
    <origin
      xyz="0 0.34 0"
      rpy="0 0 0" />
    <parent
      link="Base" />
    <child
      link="stick_2" />
    <axis
      xyz="0 0 0" />
  </joint>
  <link
    name="hook_1">
    <inertial>
      <origin
        xyz="-0.0074828 0.23347 -0.020697"
        rpy="0 0 0" />
      <mass
        value="1.0419" />
      <inertia
        ixx="0.0017085"
        ixy="-1.1165E-05"
        ixz="-5.9438E-12"
        iyy="0.00071761"
        iyz="-4.3578E-06"
        izz="0.0011807" />
    </inertial>
    <visual>
      <origin
        xyz="0 0 0"
        rpy="0 0 0" />
      <geometry>
        <mesh
          filename="meshes/hook_1.obj" />
      </geometry>
      <material
        name="">
        <color
          rgba="0.75294 0.75294 0.75294 1" />
      </material>
    </visual>
  </link>
  <joint
    name="virtul_joint_hook_1"
    type="revolute">
    <origin
      xyz="0 0 0"
      rpy="-1.5708 0 0" />
    <parent
      link="Base" />
    <child
      link="hook_1" />
    <axis
      xyz="1 0 0" />
    <limit
      lower="-3.1415926"
      upper="3.1415926"
      effort="16"
      velocity="43" />
  </joint>
  <link
    name="link_2">
    <inertial>
      <origin
        xyz="0.00039594 0.091773 3.1856E-05"
        rpy="0 0 0" />
      <mass
        value="0.49759" />
      <inertia
        ixx="0.00099182"
        ixy="-2.7785E-06"
        ixz="-1.7253E-10"
        iyy="0.0003858"
        iyz="-2.3071E-08"
        izz="0.00063822" />
    </inertial>
    <visual>
      <origin
        xyz="0 0 0"
        rpy="0 0 0" />
      <geometry>
        <mesh
          filename="meshes/link_2.obj" />
      </geometry>
      <material
        name="">
        <color
          rgba="0 0.75294 0 1" />
      </material>
    </visual>
  </link>
  <joint
    name="joint_1"
    type="revolute">
    <origin
      xyz="0.0221 0.31401 -0.02"
      rpy="0 0 0" />
    <parent
      link="hook_1" />
    <child
      link="link_2" />
    <axis
      xyz="1 0 0" />
    <limit
      lower="-3.1415926"
      upper="3.1415926"
      effort="16"
      velocity="43" />
  </joint>
  <transmission type="SimpleTransmission" name="elbow_trans">
    <actuator name="joint_1"/>
    <joint name="joint_1"/>
    <mechanicalReduction>1</mechanicalReduction>
  </transmission>    
  <link
    name="hook_2">
    <inertial>
      <origin
        xyz="0.0236 -0.035143 0.027199"
        rpy="0 0 0" />
      <mass
        value="0.1009" />
      <inertia
        ixx="0.00014182"
        ixy="-1.0624E-11"
        ixz="5.6845E-12"
        iyy="3.885E-05"
        iyz="-4.3578E-06"
        izz="0.00011814" />
    </inertial>
    <visual>
      <origin
        xyz="0 0 0"
        rpy="0 0 0" />
      <geometry>
        <mesh
          filename="meshes/hook_2.obj" />
      </geometry>
      <material
        name="">
        <color
          rgba="0.75294 0.75294 0.75294 1" />
      </material>
    </visual>
  </link>
  <joint
    name="virtual_joint_hook_2"
    type="fixed">
    <origin
      xyz="-0.0221 0.31401 -0.02"
      rpy="0 0 0" />
    <parent
      link="link_2" />
    <child
      link="hook_2" />
    <axis
      xyz="0 0 0" />
  </joint>
  <link
    name="IMU">
    <inertial>
      <origin
        xyz="0.0071635 -0.0014434 0.00087298"
        rpy="0 0 0" />
      <mass
        value="0.032575" />
      <inertia
        ixx="1.2236E-05"
        ixy="-3.9023E-07"
        ixz="-5.1339E-07"
        iyy="8.4139E-06"
        iyz="3.5873E-07"
        izz="2.0142E-05" />
    </inertial>
    <visual>
      <origin
        xyz="0 0 0"
        rpy="0 0 0" />
      <geometry>
        <mesh
          filename="meshes/IMU.obj" />
      </geometry>
      <material
        name="">
        <color
          rgba="0.2 0.2 0.2 1" />
      </material>
    </visual>
  </link>
  <joint
    name="IMU"
    type="fixed">
    <origin
      xyz="0.00959 0.15306 0.0015645"
      rpy="0 1.5708 0" />
    <parent
      link="link_2" />
    <child
      link="IMU" />
    <axis
      xyz="0 0 0" />
  </joint>
  <link
    name="stick_1">
    <inertial>
      <origin
        xyz="0 0 0"
        rpy="0 0 0" />
      <mass
        value="0" />
      <inertia
        ixx="0"
        ixy="0"
        ixz="0"
        iyy="0"
        iyz="0"
        izz="0" />
    </inertial>
    <visual>
      <origin
        xyz="0 0 0"
        rpy="0 0 0" />
      <geometry>
        <mesh
          filename="meshes/stick_1.obj" />
      </geometry>
      <material
        name="">
        <color
          rgba="1 1 1 1" />
      </material>
    </visual>
  </link>
  <joint
    name="stick_1"
    type="fixed">
    <origin
      xyz="0 -0.34 0"
      rpy="0 0 0" />
    <parent
      link="Base" />
    <child
      link="stick_1" />
    <axis
      xyz="0 0 0" />
  </joint>
</robot>
